Workbook
Name a: #REF!
Name a: #REF!
Name a: #REF!
Name a: #REF!
Name a: #REF!
Name bn: #REF!
Name bn: #REF!
Name bn: #REF!
Name bn: #REF!
Name bn: #REF!
Name CATEGORIE: #REF!
Name CATEGORIE: #REF!
Name CATEGORIE: #REF!
Name CATEGORIE: #REF!
Name CATEGORIE: #REF!
Name CERTIFICATS: #REF!
Name CERTIFICATS: #REF!
Name CERTIFICATS: #REF!
Name CERTIFICATS: #REF!
Name CERTIFICATS: #REF!
Name customer: '[1]BASE DE DONNEES'!$O$4:$O$55
Name H: #REF!
Name H: #REF!
Name H: #REF!
Name H: #REF!
Name H: #REF!
Name INDEX: '[1]BASE DE DONNEES'!$AE$4:$AE$14
Name NUANCE: #REF!
Name NUANCE: #REF!
Name NUANCE: #REF!
Name NUANCE: #REF!
Name NUANCE: #REF!
Name PI: #REF!
Name PI: #REF!
Name PI: #REF!
Name PI: #REF!
Name PI: #REF!
Name PIPI: #REF!
Name PIPI: #REF!
Name PIPI: #REF!
Name PIPI: #REF!
Name PIPI: #REF!
Name POPO: #REF!
Name POPO: #REF!
Name POPO: #REF!
Name POPO: #REF!
Name POPO: #REF!
Name PROFILS: #REF!
Name PROFILS: #REF!
Name PROFILS: #REF!
Name PROFILS: #REF!
Name PROFILS: #REF!
Name SD: #REF!
Name SD: #REF!
Name SD: #REF!
Name SD: #REF!
Name SD: #REF!
Name tsm: '[1]BASE DE DONNEES'!$G$4:$G$8
Name UI: #REF!
Name UI: #REF!

Sheet FC-REDRESSAGE
G1: =PREVI!C10 -> CIMOLAI | K1: =PREVI!C11 -> PASSERELLE DE BELVAL
M2: =PREVI!A11 -> Z128
A3: ArcelorMittal Belval & Differdange S.A. | H3: Parachèvement spécial
A4: Site de Differdange
A5: FICHE DE CONTRÔLE / Kontrollblatt | J5: REDRESSAGE / Nachrichten
A6: Check sheet / Protokół Kontroli | J6: Redress / Geomteria
A7: CDE | B7: =PREVI!A10 -> 1100633635-636 | G7: Plan n° | H7: =PREVI!A24 -> 0 | J7: Tolérance visée: | L7: EN 10034 : 1993 | N7: (h > 360)
A8: Auftrag n° | G8: Zeichen n° | J8: Toleranz visiert
A9: Order n° | G9: Plan n° | J9: Tolerance referred
A10: Zlecenie n° | G10: Rys nr | J10: Tolerancja
A19: Date | B19: Pos | C19: Rep | D19: Profil | E19: Longueur | F19: N°laminage | G19: Larg aile | H19: K+K' max | I19: K+K' relevé | J19: F-W maxi | K19: F relevé | L19: W relevé | M19: Def.Ame | N19: Contrôleur | P19: EN 10034 : 1993 | V19: (h ≤ 360)
A20: Datum | B20: Pos | C20: Pos | D20: Profil | E20: Länge | F20: Walznummer | G20: Flanschbreite | H20: K+K' max | I20: K+K' ist | J20: =IF($L$7=$P$19,T20,IF($L$7=$P$21,S20,IF($L$7=$P$20,U20,""))) -> 1mm pro m | K20: F ist | L20: W ist | M20: Stegverform | N20: Prüfer | P20: 50% EN 10034 : 1993 | S20: 0.7mm pro m | T20: 1mm pro m | U20: 0,5mm pro m | V20: (h > 360)
A21: Date | B21: Pos | C21: Mark | D21: Section | E21: Length | F21: rolling number | G21: Width flange | H21: K+K' max | I21: K+K' is | J21: =IF($L$7=$P$19,T21,IF($L$7=$P$21,S21,IF($L$7=$P$20,U21,""))) -> 1mm / m | K21: F is | L21: W is | M21: Web déf. | N21: Controller | P21: 2/3 EN 10034 : 1993 | S21: 0.7mm / m | T21: 1mm / m | U21: 0,5mm / m
A22: Data | B22: Poz | C22: Element | D22: Profil | E22: Długość | F22: Nr walcowania | G22: Szerokość | H22: K+K' max | I22: K+K' są | J22: =IF($L$7=$P$19,T22,IF($L$7=$P$21,S22,IF($L$7=$P$20,U22,""))) -> 1mm na m | K22: Fs ą | L22: W są | M22: Ugięcie | N22: Kontroler | S22: 0.7mm na m | T22: 1mm na m | U22: 0,5mm na m
B23: =SUIVI!E9 -> 1 | D23: =SUIVI!H9 -> HL1100A | E23: =SUIVI!I9 -> 11100 | F23: =SUIVI!M9 -> CZ6 | G23: 400 | H23: =IF($L$7=$P$19,IF(0.02*G23>6.5,6.5,0.02*G23),IF($L$7=$P$20,IF(0.02*G23/2>6.5,6.5,0.02*G23/2),IF($L$7=$P$21,IF(0.02*G23*2/3>6.5,6.5,0.02*G23*2/3)))) -> 6.5 | J23: =IF($N$7=$V$20,IF($L$7=$P$19,E23/1000,IF($L$7=$P$20,E23/2000,IF($L$7=$P$21,E23*2/3000))),IF($L$7=$P$19,E23*0.0015,IF($L$7=$P$20,E23*0.00075,IF($L$7=$P$21,E23*0.001)))) -> 11.1 | O23: 1
B24: =SUIVI!E10 -> 1 | D24: =SUIVI!H10 -> HL1100A | E24: =SUIVI!I10 -> 11100 | F24: =SUIVI!M10 -> CZ7 | G24: 400 | H24: =IF($L$7=$P$19,IF(0.02*G24>6.5,6.5,0.02*G24),IF($L$7=$P$20,IF(0.02*G24/2>6.5,6.5,0.02*G24/2),IF($L$7=$P$21,IF(0.02*G24*2/3>6.5,6.5,0.02*G24*2/3)))) -> 6.5 | J24: =IF($N$7=$V$20,IF($L$7=$P$19,E24/1000,IF($L$7=$P$20,E24/2000,IF($L$7=$P$21,E24*2/3000))),IF($L$7=$P$19,E24*0.0015,IF($L$7=$P$20,E24*0.00075,IF($L$7=$P$21,E24*0.001)))) -> 11.1 | O24: 2
B25: =SUIVI!E11 -> 9 | D25: =SUIVI!H11 -> HL1100A | E25: =SUIVI!I11 -> 11300 | F25: =SUIVI!M11 -> CZ52 | G25: 400 | H25: =IF($L$7=$P$19,IF(0.02*G25>6.5,6.5,0.02*G25),IF($L$7=$P$20,IF(0.02*G25/2>6.5,6.5,0.02*G25/2),IF($L$7=$P$21,IF(0.02*G25*2/3>6.5,6.5,0.02*G25*2/3)))) -> 6.5 | J25: =IF($N$7=$V$20,IF($L$7=$P$19,E25/1000,IF($L$7=$P$20,E25/2000,IF($L$7=$P$21,E25*2/3000))),IF($L$7=$P$19,E25*0.0015,IF($L$7=$P$20,E25*0.00075,IF($L$7=$P$21,E25*0.001)))) -> 11.3 | O25: 3
B26: =SUIVI!E12 -> 10 | D26: =SUIVI!H12 -> HL1100A | E26: =SUIVI!I12 -> 9200 | F26: =SUIVI!M12 -> EA15 | G26: 400 | H26: =IF($L$7=$P$19,IF(0.02*G26>6.5,6.5,0.02*G26),IF($L$7=$P$20,IF(0.02*G26/2>6.5,6.5,0.02*G26/2),IF($L$7=$P$21,IF(0.02*G26*2/3>6.5,6.5,0.02*G26*2/3)))) -> 6.5 | J26: =IF($N$7=$V$20,IF($L$7=$P$19,E26/1000,IF($L$7=$P$20,E26/2000,IF($L$7=$P$21,E26*2/3000))),IF($L$7=$P$19,E26*0.0015,IF($L$7=$P$20,E26*0.00075,IF($L$7=$P$21,E26*0.001)))) -> 9.2 | O26: 4
B27: =SUIVI!E13 -> 2 | D27: =SUIVI!H13 -> HL1100A | E27: =SUIVI!I13 -> 10700 | F27: =SUIVI!M13 -> CZ9 oder10 | G27: 400 | H27: =IF($L$7=$P$19,IF(0.02*G27>6.5,6.5,0.02*G27),IF($L$7=$P$20,IF(0.02*G27/2>6.5,6.5,0.02*G27/2),IF($L$7=$P$21,IF(0.02*G27*2/3>6.5,6.5,0.02*G27*2/3)))) -> 6.5 | J27: =IF($N$7=$V$20,IF($L$7=$P$19,E27/1000,IF($L$7=$P$20,E27/2000,IF($L$7=$P$21,E27*2/3000))),IF($L$7=$P$19,E27*0.0015,IF($L$7=$P$20,E27*0.00075,IF($L$7=$P$21,E27*0.001)))) -> 10.7 | O27: 5
B28: =SUIVI!E14 -> 38 | D28: =SUIVI!H14 -> HL1100A | E28: =SUIVI!I14 -> 10600 | F28: =SUIVI!M14 -> EC48 | G28: 400 | H28: =IF($L$7=$P$19,IF(0.02*G28>6.5,6.5,0.02*G28),IF($L$7=$P$20,IF(0.02*G28/2>6.5,6.5,0.02*G28/2),IF($L$7=$P$21,IF(0.02*G28*2/3>6.5,6.5,0.02*G28*2/3)))) -> 6.5 | J28: =IF($N$7=$V$20,IF($L$7=$P$19,E28/1000,IF($L$7=$P$20,E28/2000,IF($L$7=$P$21,E28*2/3000))),IF($L$7=$P$19,E28*0.0015,IF($L$7=$P$20,E28*0.00075,IF($L$7=$P$21,E28*0.001)))) -> 10.6 | O28: 6
B29: =SUIVI!E15 -> 38 | D29: =SUIVI!H15 -> HL1100A | E29: =SUIVI!I15 -> 10600 | F29: =SUIVI!M15 -> EC49 | G29: 400 | H29: =IF($L$7=$P$19,IF(0.02*G29>6.5,6.5,0.02*G29),IF($L$7=$P$20,IF(0.02*G29/2>6.5,6.5,0.02*G29/2),IF($L$7=$P$21,IF(0.02*G29*2/3>6.5,6.5,0.02*G29*2/3)))) -> 6.5 | J29: =IF($N$7=$V$20,IF($L$7=$P$19,E29/1000,IF($L$7=$P$20,E29/2000,IF($L$7=$P$21,E29*2/3000))),IF($L$7=$P$19,E29*0.0015,IF($L$7=$P$20,E29*0.00075,IF($L$7=$P$21,E29*0.001)))) -> 10.6 | O29: 7
B30: =SUIVI!E16 -> 38 | D30: =SUIVI!H16 -> HL1100A | E30: =SUIVI!I16 -> 10600 | F30: =SUIVI!M16 -> EC50 | G30: 400 | H30: =IF($L$7=$P$19,IF(0.02*G30>6.5,6.5,0.02*G30),IF($L$7=$P$20,IF(0.02*G30/2>6.5,6.5,0.02*G30/2),IF($L$7=$P$21,IF(0.02*G30*2/3>6.5,6.5,0.02*G30*2/3)))) -> 6.5 | J30: =IF($N$7=$V$20,IF($L$7=$P$19,E30/1000,IF($L$7=$P$20,E30/2000,IF($L$7=$P$21,E30*2/3000))),IF($L$7=$P$19,E30*0.0015,IF($L$7=$P$20,E30*0.00075,IF($L$7=$P$21,E30*0.001)))) -> 10.6 | O30: 8
B31: =SUIVI!E17 -> 38 | D31: =SUIVI!H17 -> HL1100A | E31: =SUIVI!I17 -> 10600 | F31: =SUIVI!M17 -> EC51 | G31: 400 | H31: =IF($L$7=$P$19,IF(0.02*G31>6.5,6.5,0.02*G31),IF($L$7=$P$20,IF(0.02*G31/2>6.5,6.5,0.02*G31/2),IF($L$7=$P$21,IF(0.02*G31*2/3>6.5,6.5,0.02*G31*2/3)))) -> 6.5 | J31: =IF($N$7=$V$20,IF($L$7=$P$19,E31/1000,IF($L$7=$P$20,E31/2000,IF($L$7=$P$21,E31*2/3000))),IF($L$7=$P$19,E31*0.0015,IF($L$7=$P$20,E31*0.00075,IF($L$7=$P$21,E31*0.001)))) -> 10.6 | O31: 9
B32: =SUIVI!E18 -> 27 | D32: =SUIVI!H18 -> HL1100B | E32: =SUIVI!I18 -> 15800 | F32: =SUIVI!M18 -> EC406 oder 407 | G32: 400 | H32: =IF($L$7=$P$19,IF(0.02*G32>6.5,6.5,0.02*G32),IF($L$7=$P$20,IF(0.02*G32/2>6.5,6.5,0.02*G32/2),IF($L$7=$P$21,IF(0.02*G32*2/3>6.5,6.5,0.02*G32*2/3)))) -> 6.5 | J32: =IF($N$7=$V$20,IF($L$7=$P$19,E32/1000,IF($L$7=$P$20,E32/2000,IF($L$7=$P$21,E32*2/3000))),IF($L$7=$P$19,E32*0.0015,IF($L$7=$P$20,E32*0.00075,IF($L$7=$P$21,E32*0.001)))) -> 15.8 | O32: 10
O33: 200 | P33: RECOPIE MAXIMUM
A34: Rectitude selon EN 10034:1993 | E34: hauteur (h) | F34: tolérance EN 10034 | H34: tol. 2/3 EN 10034 | J34: tol. 50% EN 10035
A35: Geradheit | E35: Höhe / height | F35: Toleranz | G35: Tolerance | H35: Toleranz | I35: Tolerance | J35: Toleranz | K35: Tolerance
A36: Staightness | E36: Wysokość | F36: tolerancja | H36: tolerancja | J36: tolerancja
A37: Rktyfikacja | E37: 80<h≤180 | F37: +/- 0.0030 x L | H37: +/- 0.0020 x L | J37: +/- 0.0015 x L
E38: 180<h≤360 | F38: +/- 0.0015 x L | H38: +/- 0.0010 x L | J38: +/- 0.0008 x L
E39: h>360 | F39: +/- 0.0010 x L | H39: +/- 0.0007 x L | J39: +/- 0.0005 x L

Sheet FC-1 BIAIS
E1: =PREVI!C10 -> CIMOLAI | I1: =PREVI!C11 -> PASSERELLE DE BELVAL
A3: ArcelorMittal Belval & Differdange S.A. | F3: FICHE DE CONTRÔLE / Kontrollblatt / Check sheet | L3: SCIE / Säge / Saw | O3: 0/+2mm
A4: Site de Differdange | I4: Protokół Kontroli | L4: Cięcie | O4: -2/+0mm
A6: Parachèvement spécial | G6: Tol. longueur visée: | I6: +/-2mm | J6: Critère d'acceptation EN 1090-2 Tab. B.6 | O6: +/-2mm
G7: Längentoleranz visiert +/- mm. | J7: Akzeptanzkriterien nach EN 1090-2 Tab. B.6 | O7: +/-3mm
G8: Length tolerance referred +/- mm | J8: Acceptance according to EN1090-2 Tab. B.6 | O8: +/-4mm
G9: Tolerancja długości +/- mm | J9: Przyjęcie wg EN 1090-2 stół B.6 | O9: +/-5mm
G11: Commande: | H11: =PREVI!$A$10 -> 1100633635-636 | I11: =PREVI!$A$11 -> Z128 | J11: =PREVI!$A$12 -> 1900015151-15087
G12: Auftrag n° /Order n° / Ziecenie n°
G14: L = | H14: A = | I14: B =
D15: H= | G15: =E20 -> 10300 | H15: =G15-I15 -> 10300 | J15: =IF(E15,DEGREES(L15),"") | L15: =IF(E15,ATAN(I15/E15),"")
A16: Date | B16: Pos | C16: Rep | D16: Profil | E16: Longueur | F16: N°laminage | G16: Longueur | H16: Longueur | I16: Biais | J16: Angle 1 (°) | K16: Contrôleur | L16: C.E.
A17: Datum | B17: Pos | C17: Pos | D17: Profil | E17: Länge Soll | F17: Walznummer | G17: Länge Ist | H17: Länge Ist | I17: Schrag | J17: Winkel 1 | K17: Prüfer | L17: S.L.
A18: Date | B18: Pos | C18: Mark | D18: Section | E18: Length | F18: rolling number | G18: Length | H18: Length | I18: Slant | J18: Angle 1 | K18: Controller | L18: Overseer
A19: Data | B19: Poz | C19: Element | D19: Profil | E19: Długość | F19: Nr walcowania | G19: Długość | H19: Długość | I19: Ukos | J19: Kat 1 | K19: Kontroler | L19: C.E.
B20: =SUIVI!Q9 -> 0 | C20: =SUIVI!R9 -> 0 | D20: =SUIVI!H9 -> HL1100A | E20: =SUIVI!J9 -> 10300 | F20: =SUIVI!S9 -> CZ6
B21: =SUIVI!Q10 -> 0 | C21: =SUIVI!R10 -> 0 | D21: =SUIVI!H10 -> HL1100A | E21: =SUIVI!J10 -> 10300 | F21: =SUIVI!S10 -> CZ7
B22: =SUIVI!Q11 -> 0 | C22: =SUIVI!R11 -> 0 | D22: =SUIVI!H11 -> HL1100A | E22: =SUIVI!J11 -> 10400 | F22: =SUIVI!S11 -> CZ52
B23: =SUIVI!Q12 -> 0 | C23: =SUIVI!R12 -> 0 | D23: =SUIVI!H12 -> HL1100A | E23: =SUIVI!J12 -> 9000 | F23: =SUIVI!S12 -> EA15
A65: Tol d'équer. EN 1090-2 D.2.7cl1 | E65: haut/larg. | F65: tolérance | H65: haut/larg. | I65: tolérance | K65: haut/larg. | L65: tolérance
A66: ausser Winkel | E66: Höhe/Breite | F66: Toleranz | H66: Höhe/Breite | I66: Toleranz | K66: Höhe/Breite | L66: Toleranz
A67: tolerance squarring | E67: wys./szer. | F67: tolerancja | H67: wys./szer. | I67: tolerancja | K67: wys./szer. | L67: tolerancja
A68: tolerancja skośności | E68: 200 | F68: 2 | H68: 600 | I68: 6 | K68: 1000 | L68: 10
E69: 300 | F69: 3 | H69: 700 | I69: 7 | K69: 1100 | L69: 11
E70: 400 | F70: 4 | H70: 800 | I70: 8
E71: 500 | F71: 5 | H71: 900 | I71: 9
A72: Tol d'équer. EN 1090-2 D.2.7cl2 | E72: haut/larg. | F72: tolérance | H72: haut/larg. | I72: tolérance | K72: haut/larg. | L72: tolérance
A73: ausser Winkel | E73: Höhe/Breite | F73: Toleranz | H73: Höhe/Breite | I73: Toleranz | K73: Höhe/Breite | L73: Toleranz
A74: tolerance squarring | E74: wys./szer. | F74: tolerancja | H74: wys./szer. | I74: tolerancja | K74: wys./szer. | L74: tolerancja
A75: tolerancja skośności | E75: 200 | F75: 0.7 | H75: 600 | I75: 2 | K75: 1000 | L75: 3.3
E76: 300 | F76: 1 | H76: 700 | I76: 2.3 | K76: 1100 | L76: 3.7
E77: 400 | F77: 1.3 | H77: 800 | I77: 2.7
E78: 500 | F78: 1.7 | H78: 900 | I78: 3
A79: Tol.d'équerre:+/-20' (0,33°) | E79: haut/larg. | F79: tolérance | H79: haut/larg. | I79: tolérance | K79: haut/larg. | L79: tolérance
A80: ausser Winkel | E80: Höhe/Breite | F80: Toleranz | H80: Höhe/Breite | I80: Toleranz | K80: Höhe/Breite | L80: Toleranz
A81: tolerance squarring | E81: wys./szer. | F81: tolerancja | H81: wys./szer. | I81: tolerancja | K81: wys./szer. | L81: tolerancja
A82: tolerancja skośności | E82: 200 | F82: 1.2 | H82: 600 | I82: 3.5 | K82: 1000 | L82: 5.8
E83: 300 | F83: 1.7 | H83: 700 | I83: 4.1 | K83: 1100 | L83: 6.4
E84: 400 | F84: 2.3 | H84: 800 | I84: 4.7
E85: 500 | F85: 2.9 | H85: 900 | I85: 5.2
...

Sheet FC-2 BIAIS
F1: =PREVI!C10 -> CIMOLAI | J1: =PREVI!C11 -> PASSERELLE DE BELVAL
A3: ArcelorMittal Belval & Differdange S.A. | F3: FICHE DE CONTRÔLE / Kontrollblatt / Check sheet | L3: SCIE / Säge / Saw | Q3: 0/+2mm
A4: Site de Differdange | I4: Protokół Kontroli | L4: Cięcie | Q4: -2/+0mm
A6: Parachèvement spécial | G6: Tol. longueur visée: | I6: +/-2mm | K6: Critère d'acceptation EN 1090-2 Tab. B.6 | Q6: +/-2mm
G7: Längentoleranz visiert +/- mm. | K7: Akzeptanzkriterien nach EN 1090-2 Tab. B.6 | Q7: +/-3mm
G8: Length tolerance referred +/-mm | K8: Acceptance according to EN1090-2 Tab. B.6 | Q8: +/-4mm
G9: Tolerancja długości +/- mm | K9: Przyjęcie wg EN 1090-2 stół B.6 | Q9: +/-5mm
G11: Commande: | I11: =PREVI!$A$10 -> 1100633635-636 | K11: =PREVI!$A$11 -> Z128 | M11: =PREVI!$A$12 -> 1900015151-15087
G12: Auftrag n° /Order n° / Ziecenie n°
G14: L = | H14: A = | I14: a = | K14: B = | L14: b = | O14: =IF(E15,ATAN(L15/E15),"")
D15: H= | G15: =E20 -> 10300 | H15: =G15-I15 -> 10300 | J15: =IF(E15,DEGREES(O15),"") | K15: =G15-L15 -> 10300 | M15: =IF(E15,DEGREES(O14),"") | O15: =IF(E15,ATAN(I15/E15),"")
A16: Date | B16: Pos | C16: Rep | D16: Profil | E16: Longueur | F16: N°laminage | G16: Longueur | H16: Longueur | I16: Biais | J16: Angle 1 (°) | K16: Longueur | L16: Biais | M16: Angle 2 (°) | N16: Contrôleur | O16: C.E.
A17: Datum | B17: Pos | C17: Pos | D17: Profil | E17: Länge Soll | F17: Walznummer | G17: Länge Ist | H17: Länge Ist | I17: Schrag | J17: Winkel 1 | K17: Länge Ist | L17: Schrag | M17: Winkel 1 | N17: Prüfer | O17: S.L.
A18: Date | B18: Pos | C18: Mark | D18: Section | E18: Length | F18: rolling number | G18: Length | H18: Length | I18: Slant | J18: Angle 1 | K18: Length | L18: Slant | M18: Angle | N18: Controller | O18: Overseer
A19: Data | B19: Poz | C19: Element | D19: Profil | E19: Długość | F19: Nr walcowania | G19: Długość | H19: Długość | I19: Ukos | J19: Kat 1 | K19: Długość | L19: Ukos | M19: Kat 1 | N19: Kontroler | O19: C.E.
B20: =SUIVI!Q9 -> 0 | C20: =SUIVI!R9 -> 0 | D20: =SUIVI!H9 -> HL1100A | E20: =SUIVI!J9 -> 10300 | F20: =SUIVI!S9 -> CZ6
B21: =SUIVI!Q10 -> 0 | C21: =SUIVI!R10 -> 0 | D21: =SUIVI!H10 -> HL1100A | E21: =SUIVI!J10 -> 10300 | F21: =SUIVI!S10 -> CZ7
B22: =SUIVI!Q11 -> 0 | C22: =SUIVI!R11 -> 0 | D22: =SUIVI!H11 -> HL1100A | E22: =SUIVI!J11 -> 10400 | F22: =SUIVI!S11 -> CZ52
B23: =SUIVI!Q12 -> 0 | C23: =SUIVI!R12 -> 0 | D23: =SUIVI!H12 -> HL1100A | E23: =SUIVI!J12 -> 9000 | F23: =SUIVI!S12 -> EA15
A65: Tol d'équer. EN 1090-2 D.2.7cl1 | E65: haut/larg. | F65: tolérance | H65: haut/larg. | I65: tolérance | K65: haut/larg. | L65: tolérance
A66: ausser Winkel | E66: Höhe/Breite | F66: Toleranz | H66: Höhe/Breite | I66: Toleranz | K66: Höhe/Breite | L66: Toleranz
A67: tolerance squarring | E67: wys./szer. | F67: tolerancja | H67: wys./szer. | I67: tolerancja | K67: wys./szer. | L67: tolerancja
A68: tolerancja skośności | E68: 200 | F68: 2 | H68: 600 | I68: 6 | K68: 1000 | L68: 10
E69: 300 | F69: 3 | H69: 700 | I69: 7 | K69: 1100 | L69: 11
E70: 400 | F70: 4 | H70: 800 | I70: 8
E71: 500 | F71: 5 | H71: 900 | I71: 9
A72: Tol d'équer. EN 1090-2 D.2.7cl2 | E72: haut/larg. | F72: tolérance | H72: haut/larg. | I72: tolérance | K72: haut/larg. | L72: tolérance
A73: ausser Winkel | E73: Höhe/Breite | F73: Toleranz | H73: Höhe/Breite | I73: Toleranz | K73: Höhe/Breite | L73: Toleranz
A74: tolerance squarring | E74: wys./szer. | F74: tolerancja | H74: wys./szer. | I74: tolerancja | K74: wys./szer. | L74: tolerancja
A75: tolerancja skośności | E75: 200 | F75: 0.7 | H75: 600 | I75: 2 | K75: 1000 | L75: 3.3
E76: 300 | F76: 1 | H76: 700 | I76: 2.3 | K76: 1100 | L76: 3.7
E77: 400 | F77: 1.3 | H77: 800 | I77: 2.7
E78: 500 | F78: 1.7 | H78: 900 | I78: 3
A79: Tol.d'équerre:+/-20' (0,33°) | E79: haut/larg. | F79: tolérance | H79: haut/larg. | I79: tolérance | K79: haut/larg. | L79: tolérance
A80: ausser Winkel | E80: Höhe/Breite | F80: Toleranz | H80: Höhe/Breite | I80: Toleranz | K80: Höhe/Breite | L80: Toleranz
A81: tolerance squarring | E81: wys./szer. | F81: tolerancja | H81: wys./szer. | I81: tolerancja | K81: wys./szer. | L81: tolerancja
A82: tolerancja skośności | E82: 200 | F82: 1.2 | H82: 600 | I82: 3.5 | K82: 1000 | L82: 5.8
E83: 300 | F83: 1.7 | H83: 700 | I83: 4.1 | K83: 1100 | L83: 6.4
E84: 400 | F84: 2.3 | H84: 800 | I84: 4.7
E85: 500 | F85: 2.9 | H85: 900 | I85: 5.2
...

Sheet FC-2 BIAIS VÉ
F1: =PREVI!C10 -> CIMOLAI | J1: =PREVI!C11 -> PASSERELLE DE BELVAL
A3: ArcelorMittal Belval & Differdange S.A. | F3: FICHE DE CONTRÔLE / Kontrollblatt / Check sheet | L3: SCIE / Säge / Saw | Q3: 0/+2mm
A4: Site de Differdange | I4: Protokół Kontroli | L4: Cięcie | Q4: -2/+0mm
A6: Parachèvement spécial | G6: Tol. longueur visée: | I6: +/-2mm | K6: Critère d'acceptation EN 1090-2 Tab. B.6 | Q6: +/-2mm
G7: Längentoleranz visiert +/- mm. | K7: Akzeptanzkriterien nach EN 1090-2 Tab. B.6 | Q7: +/-3mm
G8: Length tolerance refer. +/-mm | K8: Acceptance according to EN1090-2 Tab. B.6 | Q8: +/-4mm
G9: Tolerancja długości +/- mm | K9: Przyjęcie wg EN 1090-2 stół B.6 | Q9: +/-5mm
G11: Commande: | I11: =PREVI!$A$10 -> 1100633635-636 | K11: =PREVI!$A$11 -> Z128 | M11: =PREVI!$A$12 -> 1900015151-15087 | Q11: ENTRER H= LA LARGEUR DU PROFILÉ
G12: Auftrag n° /Order n° / Ziecenie n° | Q12: POUR COUPE DANS L'AILE
G14: L = | H14: A = | I14: a = | K14: b = | N14: =IF(E15,ATAN(K15/E15),"")
D15: H= | G15: =E20 -> 10300 | H15: =G15-(I15+K15) -> 10300 | J15: =IF(E15,DEGREES(N15),"") | L15: =IF(E15,DEGREES(N14),"") | N15: =IF(E15,ATAN(I15/E15),"")
A16: Date | B16: Pos | C16: Rep | D16: Profil | E16: Longueur | F16: N°laminage | G16: Longueur | H16: Longueur | I16: Biais | J16: Angle 1 (°) | K16: Biais | L16: Angle 2 (°) | M16: Contrôleur | N16: C.E.
A17: Datum | B17: Pos | C17: Pos | D17: Profil | E17: Länge Soll | F17: Walznummer | G17: Länge Ist | H17: Länge Ist | I17: Schrag | J17: Winkel 1 | K17: Schrag | L17: Winkel 1 | M17: Prüfer | N17: S.L.
A18: Date | B18: Pos | C18: Mark | D18: Section | E18: Length | F18: rolling number | G18: Length | H18: Length | I18: Slant | J18: Angle 1 | K18: Slant | L18: Angle | M18: Controller | N18: Overseer
A19: Data | B19: Poz | C19: Element | D19: Profil | E19: Długość | F19: Nr walcowania | G19: Długość | H19: Długość | I19: Ukos | J19: Kat 1 | K19: Ukos | L19: Kat 1 | M19: Kontroler | N19: C.E.
B20: =SUIVI!Q9 -> 0 | C20: =SUIVI!R9 -> 0 | D20: =SUIVI!H9 -> HL1100A | E20: =SUIVI!J9 -> 10300 | F20: =SUIVI!S9 -> CZ6
B21: =SUIVI!Q10 -> 0 | C21: =SUIVI!R10 -> 0 | D21: =SUIVI!H10 -> HL1100A | E21: =SUIVI!J10 -> 10300 | F21: =SUIVI!S10 -> CZ7
B22: =SUIVI!Q11 -> 0 | C22: =SUIVI!R11 -> 0 | D22: =SUIVI!H11 -> HL1100A | E22: =SUIVI!J11 -> 10400 | F22: =SUIVI!S11 -> CZ52
B23: =SUIVI!Q12 -> 0 | C23: =SUIVI!R12 -> 0 | D23: =SUIVI!H12 -> HL1100A | E23: =SUIVI!J12 -> 9000 | F23: =SUIVI!S12 -> EA15
A65: Tol d'équer. EN 1090-2 D.2.7cl1 | E65: haut/larg. | F65: tolérance | H65: haut/larg. | I65: tolérance | K65: haut/larg. | L65: tolérance
A66: ausser Winkel | E66: Höhe/Breite | F66: Toleranz | H66: Höhe/Breite | I66: Toleranz | K66: Höhe/Breite | L66: Toleranz
A67: tolerance squarring | E67: wys./szer. | F67: tolerancja | H67: wys./szer. | I67: tolerancja | K67: wys./szer. | L67: tolerancja
A68: tolerancja skośności | E68: 200 | F68: 2 | H68: 600 | I68: 6 | K68: 1000 | L68: 10
E69: 300 | F69: 3 | H69: 700 | I69: 7 | K69: 1100 | L69: 11
E70: 400 | F70: 4 | H70: 800 | I70: 8
E71: 500 | F71: 5 | H71: 900 | I71: 9
A72: Tol d'équer. EN 1090-2 D.2.7cl2 | E72: haut/larg. | F72: tolérance | H72: haut/larg. | I72: tolérance | K72: haut/larg. | L72: tolérance
A73: ausser Winkel | E73: Höhe/Breite | F73: Toleranz | H73: Höhe/Breite | I73: Toleranz | K73: Höhe/Breite | L73: Toleranz
A74: tolerance squarring | E74: wys./szer. | F74: tolerancja | H74: wys./szer. | I74: tolerancja | K74: wys./szer. | L74: tolerancja
A75: tolerancja skośności | E75: 200 | F75: 0.7 | H75: 600 | I75: 2 | K75: 1000 | L75: 3.3
E76: 300 | F76: 1 | H76: 700 | I76: 2.3 | K76: 1100 | L76: 3.7
E77: 400 | F77: 1.3 | H77: 800 | I77: 2.7
E78: 500 | F78: 1.7 | H78: 900 | I78: 3
A79: Tol.d'équerre:+/-20' (0,33°) | E79: haut/larg. | F79: tolérance | H79: haut/larg. | I79: tolérance | K79: haut/larg. | L79: tolérance
A80: ausser Winkel | E80: Höhe/Breite | F80: Toleranz | H80: Höhe/Breite | I80: Toleranz | K80: Höhe/Breite | L80: Toleranz
A81: tolerance squarring | E81: wys./szer. | F81: tolerancja | H81: wys./szer. | I81: tolerancja | K81: wys./szer. | L81: tolerancja
A82: tolerancja skośności | E82: 200 | F82: 1.2 | H82: 600 | I82: 3.5 | K82: 1000 | L82: 5.8
E83: 300 | F83: 1.7 | H83: 700 | I83: 4.1 | K83: 1100 | L83: 6.4
E84: 400 | F84: 2.3 | H84: 800 | I84: 4.7
E85: 500 | F85: 2.9 | H85: 900 | I85: 5.2
...

Sheet FC-2 BIAIS VÉ LG DIFFÉRENTES
F1: FICHE DE CONTRÔLE / Kontrollblatt / Check sheet | N1: SCIE / Säge / Saw
A2: ArcelorMittal Belval & Differdange S.A. | J2: Protokół Kontroli | K2: Protokół Kontroli | N2: Cięcie | R2: 0/+2mm
A3: Site de Differdange | R3: -2/+0mm
A4: Parachèvement spécial | G4: Tol. longueur visée: | J4: +/-2mm | L4: Critère d'acceptation EN 1090-2 Tab. B.6 | R4: +/-2mm
G5: Längentoleranz visiert +/- mm. | L5: Akzeptanzkriterien nach EN 1090-2 Tab. B.6 | R5: +/-3mm
G6: Length tolerance refer. +/-mm | L6: Acceptance according to EN1090-2 Tab. B.6 | R6: +/-4mm
G7: Tolerancja długości +/- mm | L7: Przyjęcie wg EN 1090-2 stół B.6 | R7: +/-5mm
G9: Commande: | J9: =PREVI!$A$10 -> 1100633635-636 | K9: =PREVI!$A$10 -> 1100633635-636 | M9: =PREVI!$A$11 -> Z128 | N9: =PREVI!A11 -> Z128 | P9: =PREVI!A12 -> 1900015151-15087 | R9: ENTRER H= LA LARGEUR DU PROFILÉ
G10: Auftrag n° /Order n° / Ziecenie n° | R10: POUR COUPE DANS L'AILE
E13: L = | G13: L = | H13: A = | I13: A = | J13: a = | K13: a = | M13: b = | N13: b =
A14: Date | B14: Pos | C14: Rep | D14: Profil | E14: Longueur | F14: N°laminage | G14: Longueur | H14: Longueur | I14: Longueur | J14: Biais | K14: Biais | L14: Angle 1 (°) | M14: Biais | N14: Biais | O14: Angle 2 (°) | P14: Contrôleur
A15: Datum | B15: Pos | C15: Pos | D15: Profil | E15: Länge Soll | F15: Walznummer | G15: Länge Ist | H15: Länge Ist | I15: Länge Soll | J15: Schrag soll | K15: Schrag ist | L15: Winkel 1 | M15: Schrag soll | N15: Schrag ist | O15: Winkel 1 | P15: Prüfer
A16: Date | B16: Pos | C16: Mark | D16: Section | E16: Length | F16: rolling number | G16: Length | H16: Length | I16: Length | J16: Slant | K16: Slant | L16: Angle 1 | M16: Slant | N16: Slant | O16: Angle | P16: Controller
A17: Data | B17: Poz | C17: Element | D17: Profil | E17: Długość | F17: Nr walcowania | G17: Długość | H17: Długość | I17: Długość | J17: Ukos | K17: Ukos | L17: Kat 1 | M17: Ukos | N17: Ukos | O17: Kat 1 | P17: Kontroler | Q17: H = | R17: FORMULE | S17: FORMULE | T17: FORMULE | U17: FORMULE
B18: =SUIVI!Q9 -> 0 | C18: =SUIVI!R9 -> 0 | D18: =SUIVI!H9 -> HL1100A | E18: =SUIVI!J9 -> 10300 | F18: =SUIVI!S9 -> CZ6 | H18: =E18-(J18+M18) -> 10000 | J18: 200 | L18: =S18 -> 11.309932 | M18: 100 | O18: =U18 -> 5.7105931 | Q18: 1000 | R18: =IF(E18,ATAN(J18/Q18),"") -> 0.19739556 | S18: =IF(E18,DEGREES(R18),"") -> 11.309932 | T18: =IF(E18,ATAN(M18/Q18),"") -> 0.099668652 | U18: =IF(E18,DEGREES(T18),"") -> 5.7105931
B19: =SUIVI!Q10 -> 0 | C19: =SUIVI!R10 -> 0 | D19: =SUIVI!H10 -> HL1100A | E19: =SUIVI!J10 -> 10300 | F19: =SUIVI!S10 -> CZ7 | H19: =E19-(J19+M19) -> 9950 | J19: 200 | L19: =S19 -> 11.309932 | M19: 150 | O19: =U19 -> 8.5307656 | Q19: 1000 | R19: =IF(E19,ATAN(J19/Q19),"") -> 0.19739556 | S19: =IF(E19,DEGREES(R19),"") -> 11.309932 | T19: =IF(E19,ATAN(M19/Q19),"") -> 0.14888995 | U19: =IF(E19,DEGREES(T19),"") -> 8.5307656
B20: =SUIVI!Q11 -> 0 | C20: =SUIVI!R11 -> 0 | D20: =SUIVI!H11 -> HL1100A | E20: =SUIVI!J11 -> 10400 | F20: =SUIVI!S11 -> CZ52 | H20: =E20-(J20+M20) -> 10050 | J20: 200 | L20: =S20 -> 11.309932 | M20: 150 | O20: =U20 -> 8.5307656 | Q20: 1000 | R20: =IF(E20,ATAN(J20/Q20),"") -> 0.19739556 | S20: =IF(E20,DEGREES(R20),"") -> 11.309932 | T20: =IF(E20,ATAN(M20/Q20),"") -> 0.14888995 | U20: =IF(E20,DEGREES(T20),"") -> 8.5307656
B21: =SUIVI!Q12 -> 0 | C21: =SUIVI!R12 -> 0 | D21: =SUIVI!H12 -> HL1100A | E21: =SUIVI!J12 -> 9000 | F21: =SUIVI!S12 -> EA15 | H21: =E21-(J21+M21) -> 8650 | J21: 200 | L21: =S21 -> 11.309932 | M21: 150 | O21: =U21 -> 8.5307656 | Q21: 1000 | R21: =IF(E21,ATAN(J21/Q21),"") -> 0.19739556 | S21: =IF(E21,DEGREES(R21),"") -> 11.309932 | T21: =IF(E21,ATAN(M21/Q21),"") -> 0.14888995 | U21: =IF(E21,DEGREES(T21),"") -> 8.5307656
B22: 0 | C22: 0 | D22: 0 | E22: 0 | H22: =E22-(J22+M22) -> -350 | J22: 200 | L22: =S22 | M22: 150 | O22: =U22 | Q22: 1000 | R22: =IF(E22,ATAN(J22/Q22),"") | S22: =IF(E22,DEGREES(R22),"") | T22: =IF(E22,ATAN(M22/Q22),"") | U22: =IF(E22,DEGREES(T22),"")
B23: 0 | C23: 0 | D23: 0 | E23: 0 | F23: 0 | H23: =E23-(J23+M23) -> -350 | J23: 200 | L23: =S23 | M23: 150 | O23: =U23 | Q23: 1000 | R23: =IF(E23,ATAN(J23/Q23),"") | S23: =IF(E23,DEGREES(R23),"") | T23: =IF(E23,ATAN(M23/Q23),"") | U23: =IF(E23,DEGREES(T23),"")
B24: 0 | C24: 0 | D24: 0 | E24: 0 | F24: 0 | H24: =E24-(J24+M24) -> 0 | L24: =S24 | O24: =U24 | Q24: 1000 | R24: =IF(E24,ATAN(J24/Q24),"") | S24: =IF(E24,DEGREES(R24),"") | T24: =IF(E24,ATAN(M24/Q24),"") | U24: =IF(E24,DEGREES(T24),"")
B25: 0 | C25: 0 | D25: 0 | E25: 0 | F25: 0 | H25: =E25-(J25+M25) -> 0 | L25: =S25 | O25: =U25 | Q25: 1000 | R25: =IF(E25,ATAN(J25/Q25),"") | S25: =IF(E25,DEGREES(R25),"") | T25: =IF(E25,ATAN(M25/Q25),"") | U25: =IF(E25,DEGREES(T25),"")
B26: 0 | C26: 0 | D26: 0 | E26: 0 | F26: 0 | H26: =E26-(J26+M26) -> 0 | L26: =S26 | O26: =U26 | Q26: 1000 | R26: =IF(E26,ATAN(J26/Q26),"") | S26: =IF(E26,DEGREES(R26),"") | T26: =IF(E26,ATAN(M26/Q26),"") | U26: =IF(E26,DEGREES(T26),"")
B27: 0 | C27: 0 | D27: 0 | E27: 0 | F27: 0 | H27: =E27-(J27+M27) -> 0 | L27: =S27 | O27: =U27 | Q27: 1000 | R27: =IF(E27,ATAN(J27/Q27),"") | S27: =IF(E27,DEGREES(R27),"") | T27: =IF(E27,ATAN(M27/Q27),"") | U27: =IF(E27,DEGREES(T27),"")
B28: 0 | C28: 0 | D28: 0 | E28: 0 | F28: 0 | H28: =E28-(J28+M28) -> 0 | L28: =S28 | O28: =U28 | Q28: 1000 | R28: =IF(E28,ATAN(J28/Q28),"") | S28: =IF(E28,DEGREES(R28),"") | T28: =IF(E28,ATAN(M28/Q28),"") | U28: =IF(E28,DEGREES(T28),"")
B29: 0 | C29: 0 | D29: 0 | E29: 0 | F29: 0 | H29: =E29-(J29+M29) -> 0 | L29: =S29 | O29: =U29 | Q29: 1000 | R29: =IF(E29,ATAN(J29/Q29),"") | S29: =IF(E29,DEGREES(R29),"") | T29: =IF(E29,ATAN(M29/Q29),"") | U29: =IF(E29,DEGREES(T29),"")
B30: 0 | C30: 0 | D30: 0 | E30: 0 | F30: 0 | H30: =E30-(J30+M30) -> 0 | L30: =S30 | O30: =U30 | Q30: 1000 | R30: =IF(E30,ATAN(J30/Q30),"") | S30: =IF(E30,DEGREES(R30),"") | T30: =IF(E30,ATAN(M30/Q30),"") | U30: =IF(E30,DEGREES(T30),"")
B31: 0 | C31: 0 | D31: 0 | E31: 0 | F31: 0 | H31: =E31-(J31+M31) -> 0 | L31: =S31 | O31: =U31 | Q31: 1000 | R31: =IF(E31,ATAN(J31/Q31),"") | S31: =IF(E31,DEGREES(R31),"") | T31: =IF(E31,ATAN(M31/Q31),"") | U31: =IF(E31,DEGREES(T31),"")
B32: 0 | C32: 0 | D32: 0 | E32: 0 | F32: 0 | H32: =E32-(J32+M32) -> 0 | L32: =S32 | O32: =U32 | Q32: 1000 | R32: =IF(E32,ATAN(J32/Q32),"") | S32: =IF(E32,DEGREES(R32),"") | T32: =IF(E32,ATAN(M32/Q32),"") | U32: =IF(E32,DEGREES(T32),"")
B33: 0 | C33: 0 | D33: 0 | E33: 0 | F33: 0 | H33: =E33-(J33+M33) -> 0 | L33: =S33 | O33: =U33 | Q33: 1000 | R33: =IF(E33,ATAN(J33/Q33),"") | S33: =IF(E33,DEGREES(R33),"") | T33: =IF(E33,ATAN(M33/Q33),"") | U33: =IF(E33,DEGREES(T33),"")
B34: 0 | C34: 0 | D34: 0 | E34: 0 | F34: 0 | H34: =E34-(J34+M34) -> 0 | L34: =S34 | O34: =U34 | Q34: 1000 | R34: =IF(E34,ATAN(J34/Q34),"") | S34: =IF(E34,DEGREES(R34),"") | T34: =IF(E34,ATAN(M34/Q34),"") | U34: =IF(E34,DEGREES(T34),"")
B35: 0 | C35: 0 | D35: 0 | E35: 0 | F35: 0 | H35: =E35-(J35+M35) -> 0 | L35: =S35 | O35: =U35 | Q35: 1000 | R35: =IF(E35,ATAN(J35/Q35),"") | S35: =IF(E35,DEGREES(R35),"") | T35: =IF(E35,ATAN(M35/Q35),"") | U35: =IF(E35,DEGREES(T35),"")
... B217: 0 | C217: 0 | D217: 0 | E217: 0 | F217: 0 | H217: =E217-(J217+M217) -> 0 | L217: =S217 | O217: =U217 | Q217: 1000 | R217: =IF(E217,ATAN(J217/Q217),"") | S217: =IF(E217,DEGREES(R217),"") | T217: =IF(E217,ATAN(M217/Q217),"") | U217: =IF(E217,DEGREES(T217),"")
E218: 0
A219: Tol d'équer. EN 1090-2 D.2.7cl1 | E219: haut/larg. | F219: tolérance | H219: haut/larg. | J219: tolérance | K219: tolérance | M219: haut/larg. | N219: haut/larg. | O219: tolérance
A220: ausser Winkel | E220: Höhe/Breite | F220: Toleranz | H220: Höhe/Breite | J220: Toleranz | K220: Toleranz | M220: Höhe/Breite | N220: Höhe/Breite | O220: Toleranz
A221: tolerance squarring | E221: wys./szer. | F221: tolerancja | H221: wys./szer. | J221: tolerancja | K221: tolerancja | M221: wys./szer. | N221: wys./szer. | O221: tolerancja
A222: tolerancja skośności | E222: 200 | F222: 2 | H222: 600 | J222: 6 | K222: 6 | M222: 1000 | N222: 1000 | O222: 10
E223: 300 | F223: 3 | H223: 700 | J223: 7 | K223: 7 | M223: 1100 | N223: 1100 | O223: 11
E224: 400 | F224: 4 | H224: 800 | J224: 8 | K224: 8
...

Sheet FC-ROBOT
F2: =PREVI!C10 -> CIMOLAI | J2: =PREVI!C11 -> PASSERELLE DE BELVAL
A3: ArcelorMittal Belval & Differdange S.A. | G3: Parachèvement spécial
A4: Site de Differdange
A5: FICHE DE CONTRÔLE / Kontrollblatt / Check sheet | J5: ROBOT /Roboter/Robot | P5: Règlement : DBS 918005
E6: Protokół Kontroli | K6: Robot
A7: CDE | B7: =PREVI!A10 -> 1100633635-636 | E7: =PREVI!A11 -> Z128 | G7: Plan n° | H7: =PREVI!A24 -> 0 | J7: Spécification | N7: 0/+10mm
A8: Auftrag n° | G8: Zeichen n° | J8: Vorschrift | N8: -2/+0mm | P8: +/-20' (0,33°)
A9: Order n° | G9: Plan n° | J9: Specification | N9: +/-2mm | P9: EN 1090-2 D2.7 classe 1
A10: Zlecenie n° | G10: Rys nr | J10: Specyfikacja wg | N10: +/-3mm | P10: EN 1090-2 D2.7 classe 2
A11: Tol. longueur visée: | E11: 0/+10mm | G11: Critère d'acceptation EN 1090-2 Tab. B.6 | N11: +/-4mm
A12: Längentoleranz visiert +/- mm. | G12: Akzeptanzkriterien nach EN 1090-2 Tab. B.6 | N12: +/-5mm | P12: Fascicule 66
A13: Length tolerance referred +/- mm | G13: Acceptance according to EN1090-2 Tab. B.6 | N13: 0/+100mm | P13: Livret 2.32
A14: Tolerancja długości +/- mm | G14: Przyjęcie wg EN 1090-2 stół B.6 | P14: DBS 918005
A15: Tolérance d'équerrage | E15: +/-20' (0,33°) | I15: Réception | J15: =PREVI!E8 -> 0 | P15: Exigence client
A16: Winkligkeitstol. | I16: Abnahme
A17: Tolerance squaring | I17: Receipt
A18: Tolerancja skośności | I18: Odbiór
F22: L +/-
F27: Différences/Abweichungen/difference/różnice
H28: H : Hauteur/Höhe
G29: L | H29: H : Height/wysokość
A30: Date | B30: Pos | C30: Rep | D30: Profil | E30: Longueur | F30: N°laminage | G30: longueur | H30: Parc | I30: Bureau | J30: Contrôleur | K30: C.E. | L30: Remarques
A31: Datum | B31: Pos | C31: Pos | D31: Profil | E31: Länge Soll | F31: Walznummer | G31: Länge Ist | H31: Left | I31: Right | J31: Prüfer | K31: S.L. | L31: Bemerk.
A32: Date | B32: Pos | C32: Mark | D32: Section | E32: Length | F32: rolling number | G32: Length | H32: Links | I32: Recht | J32: Controller | K32: Overseer | L32: Remarks
A33: Data | B33: Poz | C33: Element | D33: Profil | E33: Długość | F33: Nr walcowania | G33: Długość | H33: Lewo | I33: Prawo | J33: Kontroler | K33: C.E. | L33: Uwagi
B34: =SUIVI!E9 -> 1 | C34: =SUIVI!R9 -> 0 | D34: =SUIVI!H9 -> HL1100A | E34: =SUIVI!J9 -> 10300 | F34: =SUIVI!S9 -> CZ6 | M34: 1
B35: =SUIVI!E10 -> 1 | C35: =SUIVI!R10 -> 0 | D35: =SUIVI!H10 -> HL1100A | E35: =SUIVI!J10 -> 10300 | F35: =SUIVI!S10 -> CZ7 | M35: 2
B36: =SUIVI!E11 -> 9 | C36: =SUIVI!R11 -> 0 | D36: =SUIVI!H11 -> HL1100A | E36: =SUIVI!J11 -> 10400 | F36: =SUIVI!S11 -> CZ52 | M36: 3
B37: =SUIVI!E12 -> 10 | C37: =SUIVI!R12 -> 0 | D37: =SUIVI!H12 -> HL1100A | E37: =SUIVI!J12 -> 9000 | F37: =SUIVI!S12 -> EA15 | M37: 4
B38: =SUIVI!E13 -> 2 | C38: =SUIVI!R13 -> 0 | D38: =SUIVI!H13 -> HL1100A | E38: =SUIVI!J13 -> 10100 | F38: =SUIVI!S13 -> CZ9 | M38: 5
B39: =SUIVI!E14 -> 38 | C39: =SUIVI!R14 -> 0 | D39: =SUIVI!H14 -> HL1100A | E39: =SUIVI!J14 -> 10400 | F39: =SUIVI!S14 -> EC48 | M39: 6
B40: =SUIVI!E15 -> 38 | C40: =SUIVI!R15 -> 0 | D40: =SUIVI!H15 -> HL1100A | E40: =SUIVI!J15 -> 10400 | F40: =SUIVI!S15 -> EC49 | M40: 7
B41: =SUIVI!E16 -> 38 | C41: =SUIVI!R16 -> 0 | D41: =SUIVI!H16 -> HL1100A | E41: =SUIVI!J16 -> 10400 | F41: =SUIVI!S16 -> EC50 | M41: 8
B42: =SUIVI!E17 -> 38 | C42: =SUIVI!R17 -> 0 | D42: =SUIVI!H17 -> HL1100A | E42: =SUIVI!J17 -> 10400 | F42: =SUIVI!S17 -> EC51 | M42: 9
B43: =SUIVI!E18 -> 27 | C43: =SUIVI!R18 -> 0 | D43: =SUIVI!H18 -> HL1100B | E43: =SUIVI!J18 -> 5300 | F43: =SUIVI!S18 -> EC407 | M43: 10
M44: 200 | N44: RECOPIE MAXIMUM
A45: Tol.d'équerre:+/-20' (0,33°) | E45: haut/larg. | F45: tolérance | G45: haut/larg. | H45: tolérance | J45: haut/larg. | K45: tolérance
A46: ausser Winkel | E46: Höhe/Breite | F46: Toleranz | G46: Höhe/Breite | H46: Toleranz | J46: Höhe/Breite | K46: Toleranz
A47: tolerance squarring | E47: wys./szer. | F47: tolerancja | G47: wys./szer. | H47: tolerancja | J47: wys./szer. | K47: tolerancja
A48: tolerancja skośności | E48: 200 | F48: 1.2 | G48: 600 | H48: 3.5 | J48: 1000 | K48: 5.8
...

Sheet FT-NR  AUTO
U1: DOUBLE DRESSAGE + ÉQUERRAGE
U2: TOLÉRANCES RÉDUITES 0.7MM/M
A3: ArcelorMittal Belval & Differdange S.A. | E3: Parachèvement spécial
A4: Site de Differdange
D5: MACHINE: PRESSE NR | U5: POINÇONNER LE N° DE COULÉE
A6: Nom: | D6: Date: | I6: Poste: | L6: CE:
A7: Commande | B7: Profil | C7: Longueur | D7: Descriptif du travail | F7: Tronçon | G7: REP | H7: Nbre | I7: Nbre | J7: Numero | K7: Poste | L7: Poste | M7: Proven. | N7: Destin. | O7: L-LAM | W7: TOL -2 / + 0mm
C8: finie | H8: prévu | I8: réalisé | J8: laminage | K8: Asia | L8: R 3
A9: =PREVI!$A$10 -> 1100633635-636 | B9: =SUIVI!H9 -> HL1100A | C9: =SUIVI!J9 -> 10300 | D9: DOUBLE | H9: =IF(C9,1,0) -> 1 | I9: =IF(SUIVI!O9,1,0) -> 0 | J9: =SUIVI!M9 -> CZ6 | K9: =SUIVI!E9 -> 1 | L9: =SUIVI!G9 -> 10 | M9: Parc | N9: Scie | O9: =SUIVI!I9 -> 11100 | P9: 1 | T9: OPERATEUR | U9: CE | W9: TOL -0 / +2mm
A10: =PREVI!$A$11 -> Z128 | B10: =SUIVI!H10 -> HL1100A | C10: =SUIVI!J10 -> 10300 | D10: DRESSAGE | H10: =IF(C10,1,0) -> 1 | I10: =IF(SUIVI!O10,1,0) -> 0 | J10: =SUIVI!M10 -> CZ7 | K10: =SUIVI!E10 -> 1 | L10: =SUIVI!G10 -> 10 | M10: Parc | N10: Scie | O10: =SUIVI!I10 -> 11100 | P10: 2 | T10: GLODT | U10: VALLE
A11: =PREVI!$A$12 -> 1900015151-15087 | B11: =SUIVI!H11 -> HL1100A | C11: =SUIVI!J11 -> 10400 | D11: + | H11: =IF(C11,1,0) -> 1 | I11: =IF(SUIVI!O11,1,0) -> 0 | J11: =SUIVI!M11 -> CZ52 | K11: =SUIVI!E11 -> 9 | L11: =SUIVI!G11 -> 20 | M11: Parc | N11: Scie | O11: =SUIVI!I11 -> 11300 | P11: 3 | T11: SCHMISSER | U11: WELSCHER | W11: TOL + / - 2 mm
A12: =PREVI!$C$10 -> CIMOLAI | B12: =SUIVI!H12 -> HL1100A | C12: =SUIVI!J12 -> 9000 | D12: ÉQUERRAGE | H12: =IF(C12,1,0) -> 1 | I12: =IF(SUIVI!O12,1,0) -> 0 | J12: =SUIVI!M12 -> EA15 | K12: =SUIVI!E12 -> 10 | L12: =SUIVI!G12 -> 10 | M12: Parc | N12: Scie | O12: =SUIVI!I12 -> 9200 | P12: 4 | T12: NICOLI
A13: =PREVI!$C$11 -> PASSERELLE DE BELVAL | B13: =SUIVI!H13 -> HL1100A | C13: =SUIVI!J13 -> 10100 | H13: =IF(C13,1,0) -> 1 | I13: =IF(SUIVI!O13,1,0) -> 0 | J13: =SUIVI!M13 -> CZ9 oder10 | K13: =SUIVI!E13 -> 2 | L13: =SUIVI!G13 -> 20 | M13: Parc | N13: Scie | O13: =SUIVI!I13 -> 10700 | P13: 5 | W13: TOL -0 / +50mm
A14: N° de plans | B14: =SUIVI!H14 -> HL1100A | C14: =SUIVI!J14 -> 10400 | H14: =IF(C14,1,0) -> 1 | I14: =IF(SUIVI!O14,1,0) -> 0 | J14: =SUIVI!M14 -> EC48 | K14: =SUIVI!E14 -> 38 | L14: =SUIVI!G14 -> 20 | M14: Parc | N14: Scie | O14: =SUIVI!I14 -> 10600 | P14: 6 | U14: POSTE
A15: =PREVI!$A$24 -> 0 | B15: =SUIVI!H15 -> HL1100A | C15: =SUIVI!J15 -> 10400 | D15: DOUBLE | H15: =IF(C15,1,0) -> 1 | I15: =IF(SUIVI!O15,1,0) -> 0 | J15: =SUIVI!M15 -> EC49 | K15: =SUIVI!E15 -> 38 | L15: =SUIVI!G15 -> 20 | M15: Parc | N15: Scie | O15: =SUIVI!I15 -> 10600 | P15: 7 | U15: 06-14
A16: =PREVI!$A$25 -> 0 | B16: =SUIVI!H16 -> HL1100A | C16: =SUIVI!J16 -> 10400 | D16: DRESSAGE | H16: =IF(C16,1,0) -> 1 | I16: =IF(SUIVI!O16,1,0) -> 0 | J16: =SUIVI!M16 -> EC50 | K16: =SUIVI!E16 -> 38 | L16: =SUIVI!G16 -> 30 | M16: Parc | N16: Scie | O16: =SUIVI!I16 -> 10600 | P16: 8 | U16: 14-22
A17: =PREVI!$A$26 -> 0 | B17: =SUIVI!H17 -> HL1100A | C17: =SUIVI!J17 -> 10400 | D17: + | H17: =IF(C17,1,0) -> 1 | I17: =IF(SUIVI!O17,1,0) -> 0 | J17: =SUIVI!M17 -> EC51 | K17: =SUIVI!E17 -> 38 | L17: =SUIVI!G17 -> 30 | M17: Parc | N17: Scie | O17: =SUIVI!I17 -> 10600 | P17: 9 | U17: 22-06
A18: =$A$9 -> 1100633635-636 | B18: =SUIVI!H18 -> HL1100B | C18: =SUIVI!J18 -> 5300 | D18: ÉQUERRAGE | H18: =IF(C18,1,0) -> 1 | I18: =IF(SUIVI!O18,1,0) -> 0 | J18: =SUIVI!M18 -> EC406 oder 407 | K18: =SUIVI!E18 -> 27 | L18: =SUIVI!G18 -> 40 | M18: Parc | N18: Scie | O18: =SUIVI!I18 -> 15800 | P18: 10
A19: =$A$10 -> Z128 | P19: 11
A20: =$A$11 -> 1900015151-15087 | P20: 12
A21: =$A$12 -> CIMOLAI | P21: 13
A22: =$A$13 -> PASSERELLE DE BELVAL | P22: 14
A23: N° de plans | P23: 15 | R23: DOUBLE DRESSAGE + ÉQUERRAGE
A24: =$A$15 -> 0 | P24: 16 | R24: TOLÉRANCES RÉDUITES 0.7MM/M
A25: =$A$16 -> 0 | P25: 17
A26: =$A$17 -> 0 | P26: 18
A27: =$A$9 -> 1100633635-636 | P27: 19
A28: =$A$10 -> Z128 | B28: =SUIVI!#REF! -> #REF! | C28: =SUIVI!#REF! -> #REF! | D28: DRESSAGE | H28: =IF(C28,1,0) -> #REF! | I28: =IF(SUIVI!#REF!,1,0) -> #REF! | J28: =SUIVI!#REF! -> #REF! | K28: =SUIVI!#REF! -> #REF! | L28: =SUIVI!#REF! -> #REF! | M28: Parc | N28: Scie | O28: =SUIVI!#REF! -> #REF! | P28: 20
A29: =$A$11 -> 1900015151-15087 | B29: =SUIVI!#REF! -> #REF! | C29: =SUIVI!#REF! -> #REF! | D29: + | H29: =IF(C29,1,0) -> #REF! | I29: =IF(SUIVI!#REF!,1,0) -> #REF! | J29: =SUIVI!#REF! -> #REF! | K29: =SUIVI!#REF! -> #REF! | L29: =SUIVI!#REF! -> #REF! | M29: Parc | N29: Scie | O29: =SUIVI!#REF! -> #REF! | P29: 21
A30: =$A$12 -> CIMOLAI | B30: =SUIVI!#REF! -> #REF! | C30: =SUIVI!#REF! -> #REF! | D30: ÉQUERRAGE | H30: =IF(C30,1,0) -> #REF! | I30: =IF(SUIVI!#REF!,1,0) -> #REF! | J30: =SUIVI!#REF! -> #REF! | K30: =SUIVI!#REF! -> #REF! | L30: =SUIVI!#REF! -> #REF! | M30: Parc | N30: Scie | O30: =SUIVI!#REF! -> #REF! | P30: 22
A31: =$A$13 -> PASSERELLE DE BELVAL | B31: =SUIVI!#REF! -> #REF! | C31: =SUIVI!#REF! -> #REF! | H31: =IF(C31,1,0) -> #REF! | I31: =IF(SUIVI!#REF!,1,0) -> #REF! | J31: =SUIVI!#REF! -> #REF! | K31: =SUIVI!#REF! -> #REF! | L31: =SUIVI!#REF! -> #REF! | M31: Parc | N31: Scie | O31: =SUIVI!#REF! -> #REF! | P31: 23
A32: N° de plans | B32: =SUIVI!#REF! -> #REF! | C32: =SUIVI!#REF! -> #REF! | H32: =IF(C32,1,0) -> #REF! | I32: =IF(SUIVI!#REF!,1,0) -> #REF! | J32: =SUIVI!#REF! -> #REF! | K32: =SUIVI!#REF! -> #REF! | L32: =SUIVI!#REF! -> #REF! | M32: Parc | N32: Scie | O32: =SUIVI!#REF! -> #REF! | P32: 24
A33: =$A$15 -> 0 | B33: =SUIVI!#REF! -> #REF! | C33: =SUIVI!#REF! -> #REF! | D33: DOUBLE | H33: =IF(C33,1,0) -> #REF! | I33: =IF(SUIVI!#REF!,1,0) -> #REF! | J33: =SUIVI!#REF! -> #REF! | K33: =SUIVI!#REF! -> #REF! | L33: =SUIVI!#REF! -> #REF! | M33: Parc | N33: Scie | O33: =SUIVI!#REF! -> #REF! | P33: 25
A34: =$A$16 -> 0 | B34: =SUIVI!#REF! -> #REF! | C34: =SUIVI!#REF! -> #REF! | D34: DRESSAGE | H34: =IF(C34,1,0) -> #REF! | I34: =IF(SUIVI!#REF!,1,0) -> #REF! | J34: =SUIVI!#REF! -> #REF! | K34: =SUIVI!#REF! -> #REF! | L34: =SUIVI!#REF! -> #REF! | M34: Parc | N34: Scie | O34: =SUIVI!#REF! -> #REF! | P34: 26
A35: =$A$17 -> 0 | B35: =SUIVI!#REF! -> #REF! | C35: =SUIVI!#REF! -> #REF! | D35: + | H35: =IF(C35,1,0) -> #REF! | I35: =IF(SUIVI!#REF!,1,0) -> #REF! | J35: =SUIVI!#REF! -> #REF! | K35: =SUIVI!#REF! -> #REF! | L35: =SUIVI!#REF! -> #REF! | M35: Parc | N35: Scie | O35: =SUIVI!#REF! -> #REF! | P35: 27
A36: =$A$9 -> 1100633635-636 | B36: =SUIVI!#REF! -> #REF! | C36: =SUIVI!#REF! -> #REF! | D36: ÉQUERRAGE | H36: =IF(C36,1,0) -> #REF! | I36: =IF(SUIVI!#REF!,1,0) -> #REF! | J36: =SUIVI!#REF! -> #REF! | K36: =SUIVI!#REF! -> #REF! | L36: =SUIVI!#REF! -> #REF! | M36: Parc | N36: Scie | O36: =SUIVI!#REF! -> #REF! | P36: 28
A37: =$A$10 -> Z128 | B37: =SUIVI!#REF! -> #REF! | C37: =SUIVI!#REF! -> #REF! | H37: =IF(C37,1,0) -> #REF! | I37: =IF(SUIVI!#REF!,1,0) -> #REF! | J37: =SUIVI!#REF! -> #REF! | K37: =SUIVI!#REF! -> #REF! | L37: =SUIVI!#REF! -> #REF! | M37: Parc | N37: Scie | O37: =SUIVI!#REF! -> #REF! | P37: 29
A38: =$A$11 -> 1900015151-15087 | B38: =SUIVI!#REF! -> #REF! | C38: =SUIVI!#REF! -> #REF! | H38: =IF(C38,1,0) -> #REF! | I38: =IF(SUIVI!#REF!,1,0) -> #REF! | J38: =SUIVI!#REF! -> #REF! | K38: =SUIVI!#REF! -> #REF! | L38: =SUIVI!#REF! -> #REF! | M38: Parc | N38: Scie | O38: =SUIVI!#REF! -> #REF! | P38: 30
A39: =$A$12 -> CIMOLAI | B39: =SUIVI!#REF! -> #REF! | C39: =SUIVI!#REF! -> #REF! | D39: DOUBLE | H39: =IF(C39,1,0) -> #REF! | I39: =IF(SUIVI!#REF!,1,0) -> #REF! | J39: =SUIVI!#REF! -> #REF! | K39: =SUIVI!#REF! -> #REF! | L39: =SUIVI!#REF! -> #REF! | M39: Parc | N39: Scie | O39: =SUIVI!#REF! -> #REF! | P39: 31
A40: =$A$13 -> PASSERELLE DE BELVAL | B40: =SUIVI!#REF! -> #REF! | C40: =SUIVI!#REF! -> #REF! | D40: DRESSAGE | H40: =IF(C40,1,0) -> #REF! | I40: =IF(SUIVI!#REF!,1,0) -> #REF! | J40: =SUIVI!#REF! -> #REF! | K40: =SUIVI!#REF! -> #REF! | L40: =SUIVI!#REF! -> #REF! | M40: Parc | N40: Scie | O40: =SUIVI!#REF! -> #REF! | P40: 32
...

Sheet FT-US-REP
U1: DOUBLE DRESSAGE + ÉQUERRAGE
U2: TOLÉRANCES RÉDUITES 0.7MM/M
A3: ArcelorMittal Belval & Differdange S.A. | E3: Parachèvement spécial
A4: Site de Differdange
D5: MACHINE: U.S. ET REPARATION | U5: POINÇONNER LE N° DE COULÉE
A6: Nom: | D6: Date: | I6: Poste: | L6: CE:
A7: Commande | B7: Profil | C7: Longueur | D7: Descriptif du travail | F7: Tronçon | G7: REP | H7: Nbre | I7: Nbre | J7: Numero | K7: Poste | L7: Poste | M7: Proven. | N7: Destin. | O7: L-LAM | W7: TOL -2 / + 0mm
C8: finie | H8: prévu | I8: réalisé | J8: laminage | K8: Asia | L8: R 3
A9: =PREVI!$A$10 -> 1100633635-636 | B9: =SUIVI!H9 -> HL1100A | C9: =SUIVI!J9 -> 10300 | D9: CONTRÔLE | H9: =IF(C9,1,0) -> 1 | I9: =IF(SUIVI!P9,1,0) -> 0 | J9: =SUIVI!M9 -> CZ6 | K9: =SUIVI!E9 -> 1 | L9: =SUIVI!G9 -> 10 | M9: Parc | N9: Scie | O9: =SUIVI!I9 -> 11100 | P9: 1 | T9: OPERATEUR | U9: CE | W9: TOL -0 / +2mm
A10: =PREVI!$A$11 -> Z128 | B10: =SUIVI!H10 -> HL1100A | C10: =SUIVI!J10 -> 10300 | D10: ULTRA SON | H10: =IF(C10,1,0) -> 1 | I10: =IF(SUIVI!P10,1,0) -> 0 | J10: =SUIVI!M10 -> CZ7 | K10: =SUIVI!E10 -> 1 | L10: =SUIVI!G10 -> 10 | M10: Parc | N10: Scie | O10: =SUIVI!I10 -> 11100 | P10: 2 | T10: GLODT | U10: VALLE
A11: =PREVI!$A$12 -> 1900015151-15087 | B11: =SUIVI!H11 -> HL1100A | C11: =SUIVI!J11 -> 10400 | D11: 1 | H11: =IF(C11,1,0) -> 1 | I11: =IF(SUIVI!P11,1,0) -> 0 | J11: =SUIVI!M11 -> CZ52 | K11: =SUIVI!E11 -> 9 | L11: =SUIVI!G11 -> 20 | M11: Parc | N11: Scie | O11: =SUIVI!I11 -> 11300 | P11: 3 | T11: NICOLI | U11: WELSCHER | W11: TOL + / - 2 mm
A12: =PREVI!$C$10 -> CIMOLAI | B12: =SUIVI!H12 -> HL1100A | C12: =SUIVI!J12 -> 9000 | H12: =IF(C12,1,0) -> 1 | I12: =IF(SUIVI!P12,1,0) -> 0 | J12: =SUIVI!M12 -> EA15 | K12: =SUIVI!E12 -> 10 | L12: =SUIVI!G12 -> 10 | M12: Parc | N12: Scie | O12: =SUIVI!I12 -> 9200 | P12: 4 | T12: SCHMISSER
A13: =PREVI!$C$11 -> PASSERELLE DE BELVAL | B13: =SUIVI!H13 -> HL1100A | C13: =SUIVI!J13 -> 10100 | D13: CONTRÔLE ETAT | H13: =IF(C13,1,0) -> 1 | I13: =IF(SUIVI!P13,1,0) -> 0 | J13: =SUIVI!M13 -> CZ9 oder10 | K13: =SUIVI!E13 -> 2 | L13: =SUIVI!G13 -> 20 | M13: Parc | N13: Scie | O13: =SUIVI!I13 -> 10700 | P13: 5 | W13: TOL -0 / +50mm
A14: N° de plans | B14: =SUIVI!H14 -> HL1100A | C14: =SUIVI!J14 -> 10400 | D14: ET RÉPARATION | H14: =IF(C14,1,0) -> 1 | I14: =IF(SUIVI!P14,1,0) -> 0 | J14: =SUIVI!M14 -> EC48 | K14: =SUIVI!E14 -> 38 | L14: =SUIVI!G14 -> 20 | M14: Parc | N14: Scie | O14: =SUIVI!I14 -> 10600 | P14: 6 | U14: POSTE
A15: =PREVI!$A$24 -> 0 | B15: =SUIVI!H15 -> HL1100A | C15: =SUIVI!J15 -> 10400 | D15: DE SURFACE | H15: =IF(C15,1,0) -> 1 | I15: =IF(SUIVI!P15,1,0) -> 0 | J15: =SUIVI!M15 -> EC49 | K15: =SUIVI!E15 -> 38 | L15: =SUIVI!G15 -> 20 | M15: Parc | N15: Scie | O15: =SUIVI!I15 -> 10600 | P15: 7 | U15: 06-14
A16: =PREVI!$A$25 -> 0 | B16: =SUIVI!H16 -> HL1100A | C16: =SUIVI!J16 -> 10400 | H16: =IF(C16,1,0) -> 1 | I16: =IF(SUIVI!P16,1,0) -> 0 | J16: =SUIVI!M16 -> EC50 | K16: =SUIVI!E16 -> 38 | L16: =SUIVI!G16 -> 30 | M16: Parc | N16: Scie | O16: =SUIVI!I16 -> 10600 | P16: 8 | U16: 14-22
A17: =PREVI!$A$26 -> 0 | B17: =SUIVI!H17 -> HL1100A | C17: =SUIVI!J17 -> 10400 | H17: =IF(C17,1,0) -> 1 | I17: =IF(SUIVI!P17,1,0) -> 0 | J17: =SUIVI!M17 -> EC51 | K17: =SUIVI!E17 -> 38 | L17: =SUIVI!G17 -> 30 | M17: Parc | N17: Scie | O17: =SUIVI!I17 -> 10600 | P17: 9 | U17: 22-06
A18: =$A$9 -> 1100633635-636 | B18: =SUIVI!H18 -> HL1100B | C18: =SUIVI!J18 -> 5300 | H18: =IF(C18,1,0) -> 1 | I18: =IF(SUIVI!P18,1,0) -> 0 | J18: =SUIVI!M18 -> EC406 oder 407 | K18: =SUIVI!E18 -> 27 | L18: =SUIVI!G18 -> 40 | M18: Parc | N18: Scie | O18: =SUIVI!I18 -> 15800 | P18: 10
A19: =$A$10 -> Z128 | P19: 11
A20: =$A$11 -> 1900015151-15087 | P20: 12
A21: =$A$12 -> CIMOLAI | P21: 13
A22: =$A$13 -> PASSERELLE DE BELVAL | P22: 14
A23: N° de plans | P23: 15 | R23: DOUBLE DRESSAGE + ÉQUERRAGE
A24: =$A$15 -> 0 | P24: 16 | R24: TOLÉRANCES RÉDUITES 0.7MM/M
A25: =$A$16 -> 0 | P25: 17
A26: =$A$17 -> 0 | P26: 18
A27: =$A$9 -> 1100633635-636 | P27: 19
A28: =$A$10 -> Z128 | P28: 20
A29: =$A$11 -> 1900015151-15087 | P29: 21
A30: =$A$12 -> CIMOLAI | B30: =SUIVI!#REF! -> #REF! | C30: =SUIVI!#REF! -> #REF! | H30: =IF(C30,1,0) -> #REF! | I30: =IF(SUIVI!#REF!,1,0) -> #REF! | J30: =SUIVI!#REF! -> #REF! | K30: =SUIVI!#REF! -> #REF! | L30: =SUIVI!#REF! -> #REF! | M30: Parc | N30: Scie | O30: =SUIVI!#REF! -> #REF! | P30: 22
A31: =$A$13 -> PASSERELLE DE BELVAL | B31: =SUIVI!#REF! -> #REF! | C31: =SUIVI!#REF! -> #REF! | H31: =IF(C31,1,0) -> #REF! | I31: =IF(SUIVI!#REF!,1,0) -> #REF! | J31: =SUIVI!#REF! -> #REF! | K31: =SUIVI!#REF! -> #REF! | L31: =SUIVI!#REF! -> #REF! | M31: Parc | N31: Scie | O31: =SUIVI!#REF! -> #REF! | P31: 23
A32: N° de plans | B32: =SUIVI!#REF! -> #REF! | C32: =SUIVI!#REF! -> #REF! | H32: =IF(C32,1,0) -> #REF! | I32: =IF(SUIVI!#REF!,1,0) -> #REF! | J32: =SUIVI!#REF! -> #REF! | K32: =SUIVI!#REF! -> #REF! | L32: =SUIVI!#REF! -> #REF! | M32: Parc | N32: Scie | O32: =SUIVI!#REF! -> #REF! | P32: 24
A33: =$A$15 -> 0 | B33: =SUIVI!#REF! -> #REF! | C33: =SUIVI!#REF! -> #REF! | H33: =IF(C33,1,0) -> #REF! | I33: =IF(SUIVI!#REF!,1,0) -> #REF! | J33: =SUIVI!#REF! -> #REF! | K33: =SUIVI!#REF! -> #REF! | L33: =SUIVI!#REF! -> #REF! | M33: Parc | N33: Scie | O33: =SUIVI!#REF! -> #REF! | P33: 25
A34: =$A$16 -> 0 | B34: =SUIVI!#REF! -> #REF! | C34: =SUIVI!#REF! -> #REF! | H34: =IF(C34,1,0) -> #REF! | I34: =IF(SUIVI!#REF!,1,0) -> #REF! | J34: =SUIVI!#REF! -> #REF! | K34: =SUIVI!#REF! -> #REF! | L34: =SUIVI!#REF! -> #REF! | M34: Parc | N34: Scie | O34: =SUIVI!#REF! -> #REF! | P34: 26
A35: =$A$17 -> 0 | B35: =SUIVI!#REF! -> #REF! | C35: =SUIVI!#REF! -> #REF! | H35: =IF(C35,1,0) -> #REF! | I35: =IF(SUIVI!#REF!,1,0) -> #REF! | J35: =SUIVI!#REF! -> #REF! | K35: =SUIVI!#REF! -> #REF! | L35: =SUIVI!#REF! -> #REF! | M35: Parc | N35: Scie | O35: =SUIVI!#REF! -> #REF! | P35: 27
A36: =$A$9 -> 1100633635-636 | B36: =SUIVI!#REF! -> #REF! | C36: =SUIVI!#REF! -> #REF! | H36: =IF(C36,1,0) -> #REF! | I36: =IF(SUIVI!#REF!,1,0) -> #REF! | J36: =SUIVI!#REF! -> #REF! | K36: =SUIVI!#REF! -> #REF! | L36: =SUIVI!#REF! -> #REF! | M36: Parc | N36: Scie | O36: =SUIVI!#REF! -> #REF! | P36: 28
A37: =$A$10 -> Z128 | B37: =SUIVI!#REF! -> #REF! | C37: =SUIVI!#REF! -> #REF! | H37: =IF(C37,1,0) -> #REF! | I37: =IF(SUIVI!#REF!,1,0) -> #REF! | J37: =SUIVI!#REF! -> #REF! | K37: =SUIVI!#REF! -> #REF! | L37: =SUIVI!#REF! -> #REF! | M37: Parc | N37: Scie | O37: =SUIVI!#REF! -> #REF! | P37: 29
A38: =$A$11 -> 1900015151-15087 | B38: =SUIVI!#REF! -> #REF! | C38: =SUIVI!#REF! -> #REF! | H38: =IF(C38,1,0) -> #REF! | I38: =IF(SUIVI!#REF!,1,0) -> #REF! | J38: =SUIVI!#REF! -> #REF! | K38: =SUIVI!#REF! -> #REF! | L38: =SUIVI!#REF! -> #REF! | M38: Parc | N38: Scie | O38: =SUIVI!#REF! -> #REF! | P38: 30
A39: =$A$12 -> CIMOLAI | B39: =SUIVI!#REF! -> #REF! | C39: =SUIVI!#REF! -> #REF! | H39: =IF(C39,1,0) -> #REF! | I39: =IF(SUIVI!#REF!,1,0) -> #REF! | J39: =SUIVI!#REF! -> #REF! | K39: =SUIVI!#REF! -> #REF! | L39: =SUIVI!#REF! -> #REF! | M39: Parc | N39: Scie | O39: =SUIVI!#REF! -> #REF! | P39: 31
A40: =$A$13 -> PASSERELLE DE BELVAL | B40: =SUIVI!#REF! -> #REF! | C40: =SUIVI!#REF! -> #REF! | H40: =IF(C40,1,0) -> #REF! | I40: =IF(SUIVI!#REF!,1,0) -> #REF! | J40: =SUIVI!#REF! -> #REF! | K40: =SUIVI!#REF! -> #REF! | L40: =SUIVI!#REF! -> #REF! | M40: Parc | N40: Scie | O40: =SUIVI!#REF! -> #REF! | P40: 32
...

Sheet FT-SCIE
A3: ArcelorMittal Belval & Differdange S.A. | E3: Parachèvement spécial
A4: Site de Differdange
D5: MACHINE: SCIE | U5: POINÇONNER LE N° DE COULÉE
A6: Nom: | D6: Date: | I6: Poste: | L6: CE:
A7: Commande | B7: Profil | C7: Longueur | D7: Descriptif du travail | F7: Tronçon | G7: REP | H7: Nbre | I7: Nbre | J7: Numero | K7: Poste | L7: Poste | M7: Proven. | N7: Destin. | O7: L-LAM | W7: TOL -2 / + 0mm
C8: finie | H8: prévu | I8: réalisé | J8: laminage | K8: Asia | L8: R 3
A9: =PREVI!$A$10 -> 1100633635-636 | B9: =SUIVI!H9 -> HL1100A | C9: =SUIVI!J9 -> 10300 | F9: =SUIVI!Q9 -> 0 | G9: =SUIVI!R9 -> 0 | H9: =IF(C9,1,0) -> 1 | I9: =IF(SUIVI!T9,1,0) -> #VALUE! | J9: =SUIVI!S9 -> CZ6 | K9: =SUIVI!E9 -> 1 | L9: =SUIVI!G9 -> 10 | M9: PARC | N9: PARC | O9: =SUIVI!I9 -> 11100 | P9: 1 | T9: OPERATEUR | U9: CE | W9: TOL -0 / +2mm
A10: =PREVI!$A$11 -> Z128 | N10: =SUIVI!$V$8 -> LKW | P10: 2 | T10: VALLE | U10: VALLE
A11: =PREVI!$A$12 -> 1900015151-15087 | P11: 3 | T11: MUNO | U11: WELSCHER | W11: TOL + / - 2 mm
A12: =PREVI!$C$10 -> CIMOLAI | P12: 4 | T12: GLODT
A13: =PREVI!$C$11 -> PASSERELLE DE BELVAL | P13: 5 | T13: SCHOLLER | W13: TOL -0 / +50mm
A14: N° de plans | P14: 6 | T14: GONCALVES JC | U14: POSTE
A15: =PREVI!$A$24 -> 0 | P15: 7 | U15: 06-14
A16: =PREVI!$A$25 -> 0 | P16: 8 | U16: 14-22
A17: =PREVI!$A$26 -> 0 | D17: CONTRÔLE DE | P17: 9 | U17: 22-06
A18: =$A$9 -> 1100633635-636 | D18: L'ÉTAT DE | P18: 10
A19: =$A$10 -> Z128 | D19: SURFACE ET | P19: 11
A20: =$A$11 -> 1900015151-15087 | D20: ENVOYER EN | P20: 12
A21: =$A$12 -> CIMOLAI | D21: RÉPARATION | P21: 13 | S21: LG DE CHARGEMENT MAXI SUR CAMION
A22: =$A$13 -> PASSERELLE DE BELVAL | D22: SI | P22: 14 | S22: 22000 | T22: MAXI RECOMMANDÉ
A23: N° de plans | D23: NÉCESSAIRE | P23: 15 | S23: 23000 | T23: A VÉRIFIER
A24: =$A$15 -> 0 | P24: 16 | S24: 24000 | T24: fait avec casse rétroviseur
A25: =$A$16 -> 0 | P25: 17
A26: =$A$17 -> 0 | P26: 18
A27: =$A$9 -> 1100633635-636 | P27: 19
B28: F577 SCIAGE BARRE DE SCHROTT

Sheet FT-ROBOT AUTO
A3: ArcelorMittal Belval & Differdange S.A. | E3: Parachèvement spécial
A4: Site de Differdange
D5: MACHINE: ROBOT | U5: POINÇONNER LE N° DE COULÉE
A6: Nom: | B6: GERON | D6: Date: | E6: 44589 | I6: Poste: | J6: 06-14 | L6: CE:
A7: Commande | B7: Profil | C7: Longueur | D7: Descriptif du travail | F7: Tronçon | G7: REP | H7: Nbre | I7: Nbre | J7: Numero | K7: Poste | L7: Poste | M7: Proven. | N7: Destin. | O7: L-LAM | W7: TOL -2 / + 0mm
C8: finie | H8: prévu | I8: réalisé | J8: laminage | K8: Asia | L8: R 3
A9: =PREVI!$A$10 -> 1100633635-636 | B9: =SUIVI!H9 -> HL1100A | C9: =SUIVI!J9 -> 10300 | D9: 2 bouts 90° -0/+10mm | F9: =SUIVI!Q9 -> 0 | G9: =SUIVI!R9 -> 0 | H9: =IF(C9,1,0) -> 1 | I9: =IF(SUIVI!T9,1,0) -> #VALUE! | J9: =SUIVI!S9 -> CZ6 | K9: =SUIVI!E9 -> 1 | L9: =SUIVI!G9 -> 10 | M9: Parc | N9: Parc | O9: =SUIVI!I9 -> 11100 | P9: 1 | T9: OPERATEUR | U9: CE | W9: TOL -0 / +2mm
A10: =PREVI!$A$11 -> Z128 | B10: =SUIVI!H10 -> HL1100A | C10: =SUIVI!J10 -> 10300 | D10: 2 bouts 90° -0/+10mm | F10: =SUIVI!Q10 -> 0 | G10: =SUIVI!R10 -> 0 | H10: =IF(C10,1,0) -> 1 | I10: =IF(SUIVI!T10,1,0) -> #VALUE! | J10: =SUIVI!S10 -> CZ7 | K10: =SUIVI!E10 -> 1 | L10: =SUIVI!G10 -> 10 | M10: Parc | N10: =SUIVI!$V$8 -> LKW | O10: =SUIVI!I10 -> 11100 | P10: 2 | T10: SCHILS | U10: VALLE
A11: =PREVI!$A$12 -> 1900015151-15087 | B11: =SUIVI!H11 -> HL1100A | C11: =SUIVI!J11 -> 10400 | D11: 2 bouts 90° -0/+10mm | F11: =SUIVI!Q11 -> 0 | G11: =SUIVI!R11 -> 0 | H11: =IF(C11,1,0) -> 1 | I11: =IF(SUIVI!T11,1,0) -> #VALUE! | J11: =SUIVI!S11 -> CZ52 | K11: =SUIVI!E11 -> 9 | L11: =SUIVI!G11 -> 20 | M11: Parc | N11: Parc | O11: =SUIVI!I11 -> 11300 | P11: 3 | T11: GERON | U11: WELSCHER | W11: TOL + / - 2 mm
A12: =PREVI!$C$10 -> CIMOLAI | B12: =SUIVI!H12 -> HL1100A | C12: =SUIVI!J12 -> 9000 | D12: 2 bouts 90° -0/+10mm | F12: =SUIVI!Q12 -> 0 | G12: =SUIVI!R12 -> 0 | H12: =IF(C12,1,0) -> 1 | I12: =IF(SUIVI!T12,1,0) -> #VALUE! | J12: =SUIVI!S12 -> EA15 | K12: =SUIVI!E12 -> 10 | L12: =SUIVI!G12 -> 10 | M12: Parc | N12: =SUIVI!$V$8 -> LKW | O12: =SUIVI!I12 -> 9200 | P12: 4 | T12: MATHIEU
A13: =PREVI!$C$11 -> PASSERELLE DE BELVAL | B13: =SUIVI!H13 -> HL1100A | C13: =SUIVI!J13 -> 10100 | D13: 2 bouts 90° -0/+10mm | F13: =SUIVI!Q13 -> 0 | G13: =SUIVI!R13 -> 0 | H13: =IF(C13,1,0) -> 1 | I13: =IF(SUIVI!T13,1,0) -> #VALUE! | J13: =SUIVI!S13 -> CZ9 | K13: =SUIVI!E13 -> 2 | L13: =SUIVI!G13 -> 20 | M13: Parc | N13: Parc | O13: =SUIVI!I13 -> 10700 | P13: 5 | T13: MUNO | W13: TOL -0 / +50mm
A14: N° de plans | B14: =SUIVI!H14 -> HL1100A | C14: =SUIVI!J14 -> 10400 | D14: èpreuve | F14: =SUIVI!Q14 -> 0 | G14: =SUIVI!R14 -> 0 | H14: =IF(C14,1,0) -> 1 | I14: =IF(SUIVI!T14,1,0) -> #VALUE! | J14: =SUIVI!S14 -> EC48 | K14: =SUIVI!E14 -> 38 | L14: =SUIVI!G14 -> 20 | M14: Parc | N14: =SUIVI!$V$8 -> LKW | O14: =SUIVI!I14 -> 10600 | P14: 6 | T14: WIRTGEN | U14: POSTE
A15: =PREVI!$A$24 -> 0 | B15: =SUIVI!H15 -> HL1100A | C15: =SUIVI!J15 -> 10400 | D15: 2 bouts 90° -0/+10mm | F15: =SUIVI!Q15 -> 0 | G15: =SUIVI!R15 -> 0 | H15: =IF(C15,1,0) -> 1 | I15: =IF(SUIVI!T15,1,0) -> #VALUE! | J15: =SUIVI!S15 -> EC49 | K15: =SUIVI!E15 -> 38 | L15: =SUIVI!G15 -> 20 | M15: Parc | N15: Parc | O15: =SUIVI!I15 -> 10600 | P15: 7 | U15: 06-14
A16: =PREVI!$A$25 -> 0 | B16: =SUIVI!H16 -> HL1100A | C16: =SUIVI!J16 -> 10400 | D16: 2 bouts 90° -0/+10mm | F16: =SUIVI!Q16 -> 0 | G16: =SUIVI!R16 -> 0 | H16: =IF(C16,1,0) -> 1 | I16: =IF(SUIVI!T16,1,0) -> #VALUE! | J16: =SUIVI!S16 -> EC50 | K16: =SUIVI!E16 -> 38 | L16: =SUIVI!G16 -> 30 | M16: Parc | N16: =SUIVI!$V$8 -> LKW | O16: =SUIVI!I16 -> 10600 | P16: 8 | U16: 14-22
A17: =PREVI!$A$26 -> 0 | B17: =SUIVI!H17 -> HL1100A | C17: =SUIVI!J17 -> 10400 | D17: 2 bouts 90° -0/+10mm | F17: =SUIVI!Q17 -> 0 | G17: =SUIVI!R17 -> 0 | H17: =IF(C17,1,0) -> 1 | I17: =IF(SUIVI!T17,1,0) -> #VALUE! | J17: =SUIVI!S17 -> EC51 | K17: =SUIVI!E17 -> 38 | L17: =SUIVI!G17 -> 30 | M17: Parc | N17: Parc | O17: =SUIVI!I17 -> 10600 | P17: 9 | U17: 22-06
A18: =$A$9 -> 1100633635-636 | B18: =SUIVI!H18 -> HL1100B | C18: =SUIVI!J18 -> 5300 | D18: 2 bouts 90° -0/+10mm | F18: =SUIVI!Q18 -> 0 | G18: =SUIVI!R18 -> 0 | H18: =IF(C18,1,0) -> 1 | I18: =IF(SUIVI!T18,1,0) -> 1 | J18: =SUIVI!S18 -> EC407 | K18: =SUIVI!E18 -> 27 | L18: =SUIVI!G18 -> 40 | M18: Parc | N18: =SUIVI!$V$8 -> LKW | O18: =SUIVI!I18 -> 15800 | P18: 10
A19: =$A$10 -> Z128 | P19: 11
A20: =$A$11 -> 1900015151-15087 | P20: 12
A21: =$A$12 -> CIMOLAI | P21: 13 | S21: LG DE CHARGEMENT MAXI SUR CAMION
A22: =$A$13 -> PASSERELLE DE BELVAL | P22: 14 | S22: 22000 | T22: MAXI RECOMMANDÉ
A23: N° de plans | P23: 15 | S23: 23000 | T23: A VÉRIFIER
A24: =$A$15 -> 0 | P24: 16 | S24: 24000 | T24: fait avec casse rétroviseur
A25: =$A$16 -> 0 | P25: 17
A26: =$A$17 -> 0 | P26: 18
A27: =$A$9 -> 1100633635-636 | P27: 19
A28: =$A$10 -> Z128 | P28: 20 | S28: INDIQUER LES 2 APPELLATIONS (ex) WTM 27x140x336 = W690x360x500
A29: =$A$11 -> 1900015151-15087 | P29: 21
A30: =$A$12 -> CIMOLAI | B30: =SUIVI!#REF! -> #REF! | C30: =SUIVI!#REF! -> #REF! | F30: =SUIVI!#REF! -> #REF! | G30: =SUIVI!#REF! -> #REF! | H30: =IF(C30,1,0) -> #REF! | I30: =IF(SUIVI!#REF!,1,0) -> #REF! | J30: =SUIVI!#REF! -> #REF! | K30: =SUIVI!#REF! -> #REF! | L30: =SUIVI!#REF! -> #REF! | M30: Parc | N30: =SUIVI!$V$8 -> LKW | O30: =SUIVI!#REF! -> #REF! | P30: 22
A31: =$A$13 -> PASSERELLE DE BELVAL | B31: =SUIVI!#REF! -> #REF! | C31: =SUIVI!#REF! -> #REF! | F31: =SUIVI!#REF! -> #REF! | G31: =SUIVI!#REF! -> #REF! | H31: =IF(C31,1,0) -> #REF! | I31: =IF(SUIVI!#REF!,1,0) -> #REF! | J31: =SUIVI!#REF! -> #REF! | K31: =SUIVI!#REF! -> #REF! | L31: =SUIVI!#REF! -> #REF! | M31: Parc | N31: Parc | O31: =SUIVI!#REF! -> #REF! | P31: 23
A32: N° de plans | B32: =SUIVI!#REF! -> #REF! | C32: =SUIVI!#REF! -> #REF! | F32: =SUIVI!#REF! -> #REF! | G32: =SUIVI!#REF! -> #REF! | H32: =IF(C32,1,0) -> #REF! | I32: =IF(SUIVI!#REF!,1,0) -> #REF! | J32: =SUIVI!#REF! -> #REF! | K32: =SUIVI!#REF! -> #REF! | L32: =SUIVI!#REF! -> #REF! | M32: Parc | N32: =SUIVI!$V$8 -> LKW | O32: =SUIVI!#REF! -> #REF! | P32: 24
A33: =$A$15 -> 0 | B33: =SUIVI!#REF! -> #REF! | C33: =SUIVI!#REF! -> #REF! | F33: =SUIVI!#REF! -> #REF! | G33: =SUIVI!#REF! -> #REF! | H33: =IF(C33,1,0) -> #REF! | I33: =IF(SUIVI!#REF!,1,0) -> #REF! | J33: =SUIVI!#REF! -> #REF! | K33: =SUIVI!#REF! -> #REF! | L33: =SUIVI!#REF! -> #REF! | M33: Parc | N33: Parc | O33: =SUIVI!#REF! -> #REF! | P33: 25
A34: =$A$16 -> 0 | B34: =SUIVI!#REF! -> #REF! | C34: =SUIVI!#REF! -> #REF! | F34: =SUIVI!#REF! -> #REF! | G34: =SUIVI!#REF! -> #REF! | H34: =IF(C34,1,0) -> #REF! | I34: =IF(SUIVI!#REF!,1,0) -> #REF! | J34: =SUIVI!#REF! -> #REF! | K34: =SUIVI!#REF! -> #REF! | L34: =SUIVI!#REF! -> #REF! | M34: Parc | N34: =SUIVI!$V$8 -> LKW | O34: =SUIVI!#REF! -> #REF! | P34: 26
A35: =$A$17 -> 0 | B35: =SUIVI!#REF! -> #REF! | C35: =SUIVI!#REF! -> #REF! | F35: =SUIVI!#REF! -> #REF! | G35: =SUIVI!#REF! -> #REF! | H35: =IF(C35,1,0) -> #REF! | I35: =IF(SUIVI!#REF!,1,0) -> #REF! | J35: =SUIVI!#REF! -> #REF! | K35: =SUIVI!#REF! -> #REF! | L35: =SUIVI!#REF! -> #REF! | M35: Parc | N35: Parc | O35: =SUIVI!#REF! -> #REF! | P35: 27
A36: =$A$9 -> 1100633635-636 | B36: =SUIVI!#REF! -> #REF! | C36: =SUIVI!#REF! -> #REF! | F36: =SUIVI!#REF! -> #REF! | G36: =SUIVI!#REF! -> #REF! | H36: =IF(C36,1,0) -> #REF! | I36: =IF(SUIVI!#REF!,1,0) -> #REF! | J36: =SUIVI!#REF! -> #REF! | K36: =SUIVI!#REF! -> #REF! | L36: =SUIVI!#REF! -> #REF! | M36: Parc | N36: =SUIVI!$V$8 -> LKW | O36: =SUIVI!#REF! -> #REF! | P36: 28
A37: =$A$10 -> Z128 | B37: =SUIVI!#REF! -> #REF! | C37: =SUIVI!#REF! -> #REF! | F37: =SUIVI!#REF! -> #REF! | G37: =SUIVI!#REF! -> #REF! | H37: =IF(C37,1,0) -> #REF! | I37: =IF(SUIVI!#REF!,1,0) -> #REF! | J37: =SUIVI!#REF! -> #REF! | K37: =SUIVI!#REF! -> #REF! | L37: =SUIVI!#REF! -> #REF! | M37: Parc | N37: Parc | O37: =SUIVI!#REF! -> #REF! | P37: 29
A38: =$A$11 -> 1900015151-15087 | B38: =SUIVI!#REF! -> #REF! | C38: =SUIVI!#REF! -> #REF! | F38: =SUIVI!#REF! -> #REF! | G38: =SUIVI!#REF! -> #REF! | H38: =IF(C38,1,0) -> #REF! | I38: =IF(SUIVI!#REF!,1,0) -> #REF! | J38: =SUIVI!#REF! -> #REF! | K38: =SUIVI!#REF! -> #REF! | L38: =SUIVI!#REF! -> #REF! | M38: Parc | N38: =SUIVI!$V$8 -> LKW | O38: =SUIVI!#REF! -> #REF! | P38: 30
A39: =$A$12 -> CIMOLAI | B39: =SUIVI!#REF! -> #REF! | C39: =SUIVI!#REF! -> #REF! | F39: =SUIVI!#REF! -> #REF! | G39: =SUIVI!#REF! -> #REF! | H39: =IF(C39,1,0) -> #REF! | I39: =IF(SUIVI!#REF!,1,0) -> #REF! | J39: =SUIVI!#REF! -> #REF! | K39: =SUIVI!#REF! -> #REF! | L39: =SUIVI!#REF! -> #REF! | M39: Parc | N39: Parc | O39: =SUIVI!#REF! -> #REF! | P39: 31
A40: =$A$13 -> PASSERELLE DE BELVAL | B40: =SUIVI!#REF! -> #REF! | C40: =SUIVI!#REF! -> #REF! | F40: =SUIVI!#REF! -> #REF! | G40: =SUIVI!#REF! -> #REF! | H40: =IF(C40,1,0) -> #REF! | I40: =IF(SUIVI!#REF!,1,0) -> #REF! | J40: =SUIVI!#REF! -> #REF! | K40: =SUIVI!#REF! -> #REF! | L40: =SUIVI!#REF! -> #REF! | M40: Parc | N40: =SUIVI!$V$8 -> LKW | O40: =SUIVI!#REF! -> #REF! | P40: 32
